Workbook

Sheet Dicionário
A1: DICIONÁRIO DE DADOS | IF.data – Banco Central do Brasil
A3: Colunas da base de dados
A4: Coluna | B4: Nome completo | C4: Tipo | D4: O que significa na prática
A5: Instituição | B5: Nome da instituição financeira | C5: Texto | D5: Nome do banco, fintech, cooperativa ou instituição de pagamento cadastrada no Banco Central.
A6: TCB | B6: Tipo de Consolidado Bancário | C6: Código | D6: Classifica o tipo de instituição. b1 = banco comercial/múltiplo com carteira comercial (os grandes bancos); n4 = instituição de pagamento (Nubank, PicPay, Mercado Pago); b3S = cooperativa singular.
A7: SR | B7: Segmento Resolução nº 4.553/2017 | C7: Código | D7: Classifica o porte da instituição: S1 é o maior (Itaú, BB, Caixa, Bradesco, Santander), S5 é o menor. Define o nível de exigências regulatórias.
A8: TC | B8: Tipo de Controle | C8: Código | D8: 1 = Público (BB, Caixa, BNB, BNDES); 2 = Privado Nacional (Itaú, Bradesco, Nubank); 3 = Privado com Controle Estrangeiro (Santander, Citibank, JP Morgan).
A9: TD | B9: Tipo de Consolidação | C9: Código | D9: C = Conglomerado (o grupo financeiro consolidado); I = Instituição independente (instituição individual sem grupo).
A10: Cidade / UF | B10: Localização da sede | C10: Texto | D10: Cidade e estado onde a instituição tem sua sede principal registrada no Banco Central.
A11: Data | B11: Data de referência | C11: Texto | D11: Mês e ano dos dados. 09/2025 = posição de setembro de 2025.
A12: Ativo Total | B12: Total de ativos (R$ mil) | C12: Número | D12: Tudo que a instituição possui: créditos concedidos, títulos, imóveis, participações. É o principal indicador de porte de um banco.
A13: Carteira de Crédito | B13: Total de créditos concedidos (R$ mil) | C13: Número | D13: Soma de todos os empréstimos, financiamentos e créditos concedidos pela instituição a clientes. É a atividade-fim dos bancos comerciais.
A14: TVM | B14: Títulos e Valores Mobiliários (R$ mil) | C14: Número | D14: Investimentos da instituição em títulos públicos (Tesouro), títulos privados, ações e outros ativos financeiros.
A15: Passivo Exigível | B15: Total de obrigações (R$ mil) | C15: Número | D15: Tudo que a instituição deve: depósitos de clientes, captações, dívidas. A diferença entre Ativo Total e Passivo Exigível é aproximadamente o Patrimônio Líquido.
... A22: ROE | B22: Retorno sobre Patrimônio Líquido | C22: Fórmula | D22: Calculado: Lucro Líquido / Patrimônio Líquido. Mede a eficiência da instituição em gerar lucro com o capital próprio. Referência: ROE acima de 15% é considerado bom no setor.
A24: Códigos de classificação (TCB, SR, TC)
A25: Código | B25: Categoria | C25: Descrição completa | D25: Exemplos
A26: b1 | B26: TCB | C26: Banco Comercial, Banco Múltiplo com Carteira Comercial ou Caixa Econômica | D26: Itaú, BB, Caixa, Bradesco, Santander, Nubank (banco)
A27: b2 | B27: TCB | C27: Banco Múltiplo sem Carteira Comercial, Banco de Investimento ou Câmbio | D27: Goldman Sachs, Banco Volkswagen, Stellantis
A28: b3S | B28: TCB | C28: Cooperativa de Crédito Singular | D28: Sicredi (cooperativas individuais), Sicoob singular
A29: b3C | B29: TCB | C29: Central e Confederação de Cooperativas de Crédito | D29: Sicoob Central, Sicredi Central
A30: b4 | B30: TCB | C30: Banco de Desenvolvimento | D30: BNDES, BNB, BRDE, Banco da Amazônia
A31: n1 | B31: TCB | C31: Não Bancário de Crédito (financeiras, SCDs) | D31: Porto Seguro Financeiro, Stone Financeiro
A32: n2 | B32: TCB | C32: Não Bancário de Mercado de Capitais (corretoras, DTVM) | D32: Corretoras de câmbio e valores
A33: n4 | B33: TCB | C33: Instituição de Pagamento | D33: Mercado Pago, PicPay, Cielo, Stone IP, PagSeguro
A34: S1 | B34: SR | C34: Segmento 1 – Porte sistêmico (> 10% do PIB ou atividade internacional) | D34: Itaú, BB, Caixa, Bradesco, Santander
A35: S2 | B35: SR | C35: Segmento 2 – Porte grande (> 1% do PIB) | D35: BNDES, BTG Pactual, XP, Safra, Nubank
A36: S3 | B36: SR | C36: Segmento 3 – Porte médio | D36: Daycoval, Inter, BRB, BMG, ABC-Brasil
... A41: 3 | B41: TC | C41: Controle Privado Estrangeiro | D41: Santander (ES), Citibank (EUA), JP Morgan (EUA), BNP Paribas (FR)

Sheet IFData_6_2026
A1: Instituição | B1: TCB | C1: Segmento (SR) | D1: Controle (TC) | E1: Tipo de Controle | F1: Cidade | G1: UF | H1: Ativo Total | I1: Carteira de Crédito (R$ mil) | J1: TVM (R$ mil) | K1: Passivo Exigível (R$ mil) | L1: Captações (R$ mil) | M1: Patrimônio Líquido (R$ mil) | N1: Lucro Líquido (R$ mil) | O1: Agências | P1: Postos de Atendimento | Q1: Carteira de Crédito/Ativo Total (%) | R1: ROE (%)
A2: ITAU | B2: b1 | C2: S1 | D2: 2 | E2: Privado Nacional | F2: SAO PAULO | G2: SP | H2: 2845762304 | I2: 1190712067 | J2: 704331459 | K2: 2629336116 | L2: 2216192439 | M2: 216426189 | N2: 24035567 | O2: 1373 | P2: 141 | Q2: 0.41841585 | R2: 0.11105665
A3: BB | B3: b1 | C3: S1 | D3: 1 | E3: Público | F3: BRASILIA | G3: DF | H3: 2583811190 | I3: 1128399194 | J3: 764075396 | K3: 2401239327 | L3: 2068469942 | M3: 182571863 | N3: 6516219 | O3: 3939 | P3: 309 | Q3: 0.43671891 | R3: 0.035691255
A4: CAIXA | B4: b1 | C4: S1 | D4: 1 | E4: Público | F4: BRASILIA | G4: DF | H4: 2368233902 | I4: 1362330927 | J4: 453110713 | K4: 2249866109 | L4: 2063880326 | M4: 118367792 | N4: 6585794 | O4: 3002 | P4: 868 | Q4: 0.57525185 | R4: 0.055638395
A5: BRADESCO | B5: b1 | C5: S1 | D5: 2 | E5: Privado Nacional | F5: OSASCO | G5: SP | H5: 2043928673 | I5: 928041485 | J5: 370340548 | K5: 1858128289 | L5: 1600488225 | M5: 185800384 | N5: 12140246 | O5: 2059 | P5: 767 | Q5: 0.45404788 | R5: 0.065340263
A6: SANTANDER | B6: b1 | C6: S1 | D6: 3 | E6: Privado Estrangeiro | F6: SAO PAULO | G6: SP | H6: 1318054939 | I6: 541757522 | J6: 291663631 | K6: 1217931666 | L6: 1020013939 | M6: 100123273 | N6: 7524653 | O6: 1214 | P6: 2516 | Q6: 0.41102803 | R6: 0.075153886
A7: BNDES | B7: b4 | C7: S2 | D7: 1 | E7: Público | F7: RIO DE JANEIRO | G7: RJ | H7: 1073403746 | I7: 375703869 | J7: 209161034 | K7: 892700475 | L7: 661452493 | M7: 180703272 | N7: 11153448 | O7: 5 | P7: 0 | Q7: 0.3500117 | R7: 0.061722446
A8: BTG PACTUAL | B8: b1 | C8: S1 | D8: 2 | E8: Privado Nacional | F8: RIO DE JANEIRO | G8: RJ | H8: 886560321 | I8: 175495662 | J8: 284109682 | K8: 806656212 | L8: 629968763 | M8: 79904110 | N8: 9471540 | O8: 68 | P8: 0 | Q8: 0.19795118 | R8: 0.11853633
A9: XP | B9: b1 | C9: S2 | D9: 2 | E9: Privado Nacional | F9: RIO DE JANEIRO | G9: RJ | H9: 347231502 | I9: 35724234 | J9: 119764884 | K9: 334789433 | L9: 257969286 | M9: 12442070 | N9: 366568 | O9: 12 | P9: 0 | Q9: 0.10288304 | R9: 0.029461979
A10: SAFRA | B10: b1 | C10: S2 | D10: 2 | E10: Privado Nacional | F10: SAO PAULO | G10: SP | H10: 276259563 | I10: 139176940 | J10: 58167274 | K10: 257595743 | L10: 217838087 | M10: 18663820 | N10: 1911887 | O10: 189 | P10: 3 | Q10: 0.50379049 | R10: 0.10243814
A11: NUBANK | B11: n1 | C11: S2 | D11: 3 | E11: Privado Estrangeiro | F11: SAO PAULO | G11: SP | H11: 267997089 | I11: 76080601 | J11: 83850989 | K11: 252978506 | L11: 225883144 | M11: 15018583 | N11: 4194823 | O11: 4 | P11: 0 | Q11: 0.28388592 | R11: 0.27930884
A12: BANCO COOPERATIVO SICREDI S.A. | B12: b1 | C12: S2 | D12: 2 | E12: Privado Nacional | F12: PORTO ALEGRE | G12: RS | H12: 234406077 | I12: 50267293 | J12: 49289841 | K12: 228925803 | L12: 202089776 | M12: 5480274 | N12: 162608 | O12: 6 | P12: 0 | Q12: 0.21444535 | R12: 0.029671509
A13: BANCO SICOOB | B13: b1 | C13: S2 | D13: 2 | E13: Privado Nacional | F13: BRASILIA | G13: DF | H13: 223147166 | I13: 44908980 | J13: 68401403 | K13: 216162767 | L13: 188184228 | M13: 6984398 | N13: 458952 | O13: 7 | P13: 0 | Q13: 0.20125275 | R13: 0.065711032
... A1407: CONSEGTUR CORRETORA DE CÂMBIO LTDA. | B1407: n2 | C1407: S5 | D1407: 2 | E1407: Privado Nacional | F1407: SAO PAULO | G1407: SP | H1407: 365 | I1407: 0 | J1407: 333 | K1407: 143 | L1407: 0 | M1407: 222 | N1407: -178 | O1407: 2 | P1407: 0 | Q1407: 0 | R1407: -0.8018018

Sheet Tabelas
A1: CÁLCULO PARA GRÁFICOS
A3: Segmento | B3: Qtd Instituições | D3: Segmento | E3: Qtd Instituições
A4: S1 | B4: 10 | D4: =A4 -> S1 | E4: =B4 -> 10
A5: S2 | B5: 14 | D5: =A5 -> S2 | E5: =B5 -> 14
A6: S3 | B6: 71 | D6: =A6 -> S3 | E6: =B6 -> 71
A7: NA | B7: 130 | D7: =A7 -> NA | E7: =B7 -> 130
A8: S4 | B8: 391 | D8: =A8 -> S4 | E8: =B8 -> 391
A9: S5 | B9: 790 | D9: =A9 -> S5 | E9: =B9 -> 790
A10: Grand Total | B10: 1406
A12: Tipo de Controle | B12: Qtd Instituições | D12: Tipo de Controle | E12: Qtd Instituições
A13: Público | B13: 29 | D13: =A13 -> Público | E13: =B13 -> 29
A14: Privado Estrangeiro | B14: 173 | D14: =A14 -> Privado Estrangeiro | E14: =B14 -> 173
A15: Privado Nacional | B15: 1204 | D15: =A15 -> Privado Nacional | E15: =B15 -> 1204
A16: Grand Total | B16: 1406 | D16: =A16 -> Grand Total | E16: =B16 -> 1406
A18: Segmento | B18: Ativo Total | D18: Segmento | E18: Ativo Total
A19: NA | B19: 158921710 | D19: =A19 -> NA | E19: =B19 -> 158921710
A20: S5 | B20: 512557103 | D20: =A20 -> S5 | E20: =B20 -> 512557103
A21: S4 | B21: 942098679 | D21: =A21 -> S4 | E21: =B21 -> 942098679
A22: S3 | B22: 2412543434 | D22: =A22 -> S3 | E22: =B22 -> 2412543434
A23: S2 | B23: 3132959342 | D23: =A23 -> S2 | E23: =B23 -> 3132959342
A24: S1 | B24: 12299822252 | D24: =A24 -> S1 | E24: =B24 -> 12299822252
A25: Grand Total | B25: 19458902520
A27: Tipo de Controle | B27: Ativo Total | D27: Tipo de Controle | E27: Ativo Total
A28: Privado Estrangeiro | B28: 3257438553 | D28: =A28 -> Privado Estrangeiro | E28: =B28 -> 3257438553
A29: Público | B29: 6497590725 | D29: =A29 -> Público | E29: =B29 -> 6497590725
A30: Privado Nacional | B30: 9703873242 | D30: =A30 -> Privado Nacional | E30: =B30 -> 9703873242
A31: Grand Total | B31: 19458902520
A33: Tipo de Controle | B33: Nº de Instituições
A34: Privado Nacional | B34: 1204
A35: Privado Estrangeiro | B35: 173
A36: Público | B36: 29
A37: Grand Total | B37: 1406
A39: Segmento | B39: Ativo Total | D39: Segmento | E39: Ativo Total | F39: % Ativo Total | G39: % Ativo Total Acum.
A40: NUBANK | B40: 267997089 | D40: =A40 -> NUBANK | E40: =B40 -> 267997089 | F40: =Table6[[#This Row],[Ativo Total]]/SUM(IFdata_6_2026[[Ativo Total ]]) -> 0.013772467 | G40: =Table6[[#This Row],[% Ativo Total ]] -> 0.013772467
A41: SAFRA | B41: 276259563 | D41: =A41 -> SAFRA | E41: =B41 -> 276259563 | F41: =Table6[[#This Row],[Ativo Total]]/SUM(IFdata_6_2026[[Ativo Total ]]) -> 0.014197078 | G41: =G40+Table6[[#This Row],[% Ativo Total ]] -> 0.027969545
A42: XP | B42: 347231502 | D42: =A42 -> XP | E42: =B42 -> 347231502 | F42: =Table6[[#This Row],[Ativo Total]]/SUM(IFdata_6_2026[[Ativo Total ]]) -> 0.017844352 | G42: =G41+Table6[[#This Row],[% Ativo Total ]] -> 0.045813897
A43: BTG PACTUAL | B43: 886560321 | D43: =A43 -> BTG PACTUAL | E43: =B43 -> 886560321 | F43: =Table6[[#This Row],[Ativo Total]]/SUM(IFdata_6_2026[[Ativo Total ]]) -> 0.045560654 | G43: =G42+Table6[[#This Row],[% Ativo Total ]] -> 0.091374551
A44: BNDES | B44: 1073403746 | D44: =A44 -> BNDES | E44: =B44 -> 1073403746 | F44: =Table6[[#This Row],[Ativo Total]]/SUM(IFdata_6_2026[[Ativo Total ]]) -> 0.055162605 | G44: =G43+Table6[[#This Row],[% Ativo Total ]] -> 0.14653716
A45: SANTANDER | B45: 1318054939 | D45: =A45 -> SANTANDER | E45: =B45 -> 1318054939 | F45: =Table6[[#This Row],[Ativo Total]]/SUM(IFdata_6_2026[[Ativo Total ]]) -> 0.067735317 | G45: =G44+Table6[[#This Row],[% Ativo Total ]] -> 0.21427247
A46: BRADESCO | B46: 2043928673 | D46: =A46 -> BRADESCO | E46: =B46 -> 2043928673 | F46: =Table6[[#This Row],[Ativo Total]]/SUM(IFdata_6_2026[[Ativo Total ]]) -> 0.10503823 | G46: =G45+Table6[[#This Row],[% Ativo Total ]] -> 0.3193107
...

Sheet Gráficos Tec-Exec
A1: ONDE ESTÃO CONCENTRADAS AS INSTITUIÇÕES
A15: ANÁLISE GRÁFICA - QUEM CONCENTRA O DINHEIRO
A32: ANÁLISE GRÁFICA - CONCENTRAÇÃO DO SISTEMA
A50: DISTRIBUIÇÃO DE ROE (%)

Sheet Análise
A1: ANÁLISE | VERSÃO COMPLETA DISPONÍVEL NO GITHUB
A4: 1. CONTEXTO DA ANÁLISE
A5: Objetivo | B5: Responder às seguintes perguntas de negócio: (1) Como os ativos estão distribuídos entre as instituições financeiras brasileiras? (2) Existe concentração relevante de mercado? (3) Qual a participação das instituições públicas no sistema financeiro? (4) Como está distribuída a rentabilidade (ROE) das instituições? (5) Há evidências de transformação digital no setor?
A6: Por que essa análise importa? | B6: Esta análise é importante porque a estrutura do sistema financeiro influencia concorrência, acesso ao crédito, estabilidade econômica e oportunidades de mercado para novos participantes.
A7: Base de dados utilizada | B7: IFData – Banco Central do Brasil
A8: Período analisado | B8: Junho/2026
A9: Tipo de instituições | B9: Conglomerados Financeiros e Instituições Independentes
A11: 2. PRINCIPAIS INDICADORES
A12: ✅ Quantidade de Instituições | B12: =COUNTA(IFdata_6_2026[Instituição]) -> 1406
A13: ✅ Ativo Total Agregado | B13: =SUM(IFdata_6_2026[[Ativo Total ]]) -> 19458902520
A14: ✅ Participação Pública no Ativo Total | B14: =SUMIF(IFdata_6_2026[Controle (TC)], 1, IFdata_6_2026[[Ativo Total ]])/B13 -> 0.33391352
A15: ✅ Ativo Total Médio | B15: =AVERAGE(IFdata_6_2026[[Ativo Total ]]) -> 13839902
A16: ✅ Ativo Total Mediano | B16: =MEDIAN(IFdata_6_2026[[Ativo Total ]]) -> 285688
A17: ✅ Carteira de Crédito Mediano | B17: =MEDIAN(IFdata_6_2026[Carteira de Crédito (R$ mil)]) -> 50082.5
A18: ✅ Número de Instituições sem Agências | B18: =COUNTIF(IFdata_6_2026[Agências], 0) -> 739
A19: ✅ ROE Médio | B19: =AVERAGE(IFdata_6_2026[ROE (%)]) -> 0.022466294
A20: ✅ ROE Mediano | B20: =MEDIAN(IFdata_6_2026[ROE (%)]) -> 0.044225499
A22: 3. INSIGHT PRINCIPAL
A23: Insight principal | B23: Embora o sistema financeiro brasileiro seja composto por mais de mil instituições, a maior parte dos ativos permanece concentrada em um grupo reduzido de organizações de grande porte.
A24: Evidência 1 | B24: Apenas 10 instituições pertencem ao segmento S1.
A25: Evidência 2 | B25: O segmento S1 concentra aproximadamente R$ 12,3 trilhões em ativos, cerca de 63% do total analisado.
A26: Evidência 3 | B26: O ativo médio é aproximadamente 48 vezes superior ao ativo mediano.
A27: Evidência 4 | B27: Mais de 70% das instituições da base não possuem agências físicas.
A29: 4. IMPLICAÇÕES
A30: Para o setor financeiro | B30: Os resultados indicam uma estrutura de mercado altamente concentrada, na qual poucas instituições exercem influência significativa sobre a oferta de crédito e a intermediação financeira. Ao mesmo tempo, a elevada quantidade de instituições sem agências físicas sugere avanço dos modelos digitais e redução da dependência de estruturas presenciais.
A31: O que isso significa para um analista de dados? | B31: A análise demonstra a importância de combinar medidas de tendência central, dispersão e concentração para evitar conclusões baseadas exclusivamente em médias agregadas. O estudo também evidencia a relevância da análise exploratória na identificação de assimetrias, outliers e padrões estruturais dos dados.
A33: 5. PRÓXIMOS PASSOS / O QUE INVESTIGAR
A34: Possíveis extensões desta análise incluem: Avaliação da evolução histórica dos ativos e da carteira de crédito. Estudo da evolução da concentração bancária ao longo do tempo. Análise da relação entre porte e rentabilidade. Comparação dos indicadores entre tipos de controle. Construção de dashboards interativos em Power BI.

Sheet Dashboard Executivo - P1
D1: SISTEMA FINANCEIRO BRASILEIRO | IFDATA 6-2026
D5: Análise Exploratória de 1.406 Instituições | Conglomerados Financeiros e Instituições Independentes
D7: Instituições | AG7: Ativo Total | BJ7: Ativo Total Público | CM7: Ativo Total Médio | DP7: Ativo Total Mediano | ES7: Carteira Crédito Mediano | FV7: Instituições sem Agências | GY7: ROE Mediano
D10: =Análise!B12 -> 1406 | AG10: =Análise!B13 -> 19458902520 | BJ10: =Análise!B14 -> 0.33391352 | CM10: =Análise!B15 -> 13839902 | DP10: =Análise!B16 -> 285688 | ES10: =Análise!B17 -> 50082.5 | FV10: =Análise!B18 -> 739 | GY10: =Análise!B20 -> 0.044225499
D16: Quantidade de Instituições por Segmento | DP16: Quantidade de Instituições por Tipo de Controle
D42: Ativo Total por Segmento | DP42: Ativo Total por Tipo de Controle
D68: Insight Principal
D71: O mercado financeiro brasileiro apresenta uma elevada concentração estrutural e financeira, com o segmento S1 retendo 63% dos ativos (R$ 12,3 trilhões) em apenas 10 instituições, enquanto a esmagadora maioria das entidades de menor porte detém parcelas reduzidas dos recursos. Sob a ótica de controle, o sistema exibe uma predominância numérica massiva de instituições privadas nacionais (1.204) em comparação às privadas estrangeiras (173) e públicas (29). Contudo, em termos de volume de capital, o cenário se reequilibra: as instituições privadas nacionais concentram a maior fatia de ativos, mas o Estado retém cerca de um terço do total, consolidando o papel estratégico do controle público na intermediação financeira do país.

Sheet Dashboard Executivo - P2
D1: SISTEMA FINANCEIRO BRASILEIRO | IFDATA 6-2026
D5: Análise Exploratória de 1.406 Instituições | Conglomerados Financeiros e Instituições Independentes
D7: Instituições | AG7: Ativo Total | BJ7: Ativo Total Público | CM7: Ativo Total Médio | DP7: Ativo Total Mediano | ES7: Carteira Crédito Mediano | FV7: Instituições sem Agências | GY7: ROE Mediano
D10: =Análise!B12 -> 1406 | AG10: =Análise!B13 -> 19458902520 | BJ10: =Análise!B14 -> 0.33391352 | CM10: =Análise!B15 -> 13839902 | DP10: =Análise!B16 -> 285688 | ES10: =Análise!B17 -> 50082.5 | FV10: =Análise!B18 -> 739 | GY10: =Análise!B20 -> 0.044225499
D16: Top 10 Instituições por Ativo Total | DP16: Curva de Pareto dos Maiores Bancos por Ativo Total
D42: Distribuição do Ativo Total por Segmento | DP42: Distribuição do ROE por Segmento
D72: Insight Principal
D75: Os resultados da amostra apresentam uma forte assimetria e concentração de mercado, onde o topo do ranking de ativos é liderado por Itaú, Banco do Brasil, Caixa, Bradesco e Santander. A Curva de Pareto e a distribuição por boxplot confirmam essa estrutura, mostrando que um grupo reduzido de grandes bancos detém a maior fatia dos recursos, gerando uma ampla dispersão de valores e uma grande diferença entre o ativo médio e o mediano. No campo da rentabilidade, a distribuição do ROE por segmento revela alta variabilidade e a presença de fortes outliers negativos, o que distorce a visibilidade dos quartis e puxa o ROE médio para 2,25%, bem abaixo da mediana de 4,42%, evidenciando que o desempenho severamente baixo de algumas instituições impacta o resultado agregado do setor.
